<?xml version="1.0" ?>
<!-- =================================================================================== -->
<!-- |    This document was autogenerated by xacro from src/wheelchair-automation/wheelchair_description/urdf/wheelchair_with_swivels.xacro | -->
<!-- |    EDITING THIS FILE BY HAND IS NOT RECOMMENDED                                 | -->
<!-- =================================================================================== -->
<robot name="wheelchair" xmlns:xacro="http://www.ros.org/wiki/xacro">
  <!-- From front wheel right joint to front wheel left joint -->
  <!-- From front wheel joint to back wheel joint -->
  <!-- From front wheel joint to head rest -->
  <link name="base_footprint">
    <visual>
      <origin rpy="0 0 0" xyz="0 0 0"/>
      <geometry>
        <box size="0.001 0.001 0.001"/>
      </geometry>
    </visual>
  </link>
  <joint name="base_footprint_joint" type="fixed">
    <origin rpy="0 0 0" xyz=" 0 0 0"/>
    <parent link="base_footprint"/>
    <child link="base_link"/>
  </joint>
  <link name="base_link">
    <visual>
      <geometry>
        <box size="0.812 0.643 1.191"/>
      </geometry>
      <material name="white">
        <color rgba="1 1 1 1"/>
      </material>
    </visual>
    <collision>
      <geometry>
        <box size="0.812 0.643 1.191"/>
      </geometry>
    </collision>
    <inertial>
      <mass value="10.0"/>
      <inertia ixx="1.66916666667" ixy="0" ixz="0" iyy="1.2125" iyz="0" izz="1.52833333333"/>
    </inertial>
  </link>
  <!--Legs -->
  <link name="legs">
    <visual>
      <geometry>
        <box size="0.4064 0.4064 0.4064"/>
      </geometry>
      <material name="white">
        <color rgba="1 1 1 1"/>
      </material>
    </visual>
    <collision>
      <geometry>
        <box size="0.4064 0.4064 0.4064"/>
      </geometry>
    </collision>
    <inertial>
      <mass value="2.0"/>
      <inertia ixx="0.135466666667" ixy="0" ixz="0" iyy="0.135466666667" iyz="0" izz="0.135466666667"/>
    </inertial>
  </link>
  <joint name="legs_joint" type="fixed">
    <axis xyz="0 0 0"/>
    <parent link="base_link"/>
    <child link="legs"/>
    <origin rpy="0 0 0" xyz="0.6092 0 -0.3923"/>
    <!--chair_height/4 + chair_height/8 because this is relative to the center of the bar -->
  </joint>
  <!--Right Bar -->
  <link name="right_bar">
    <visual>
      <geometry>
        <box size="1.015 0.16075 0.148875"/>
      </geometry>
      <material name="white">
        <color rgba="1 1 1 1"/>
      </material>
    </visual>
    <collision>
      <geometry>
        <box size="1.015 0.16075 0.148875"/>
      </geometry>
    </collision>
    <inertial>
      <mass value="2.0"/>
      <inertia ixx="1e-3" ixy="1e-3" ixz="1e-3" iyy="1e-3" iyz="1e-3" izz="1e-3"/>
    </inertial>
  </link>
  <joint name="right_bar_joint" type="fixed">
    <axis xyz="0 0 0"/>
    <parent link="base_link"/>
    <child link="right_bar"/>
    <origin rpy="0 0 0" xyz="0.0 0.3215 -0.446625"/>
    <!--chair_height/4 + chair_height/8 because this is relative to the center of the bar -->
  </joint>
  <!--Left Bar -->
  <link name="left_bar">
    <visual>
      <geometry>
        <box size="1.015 0.16075 0.148875"/>
      </geometry>
      <material name="white">
        <color rgba="1 1 1 1"/>
      </material>
    </visual>
    <collision>
      <geometry>
        <box size="1.015 0.16075 0.148875"/>
      </geometry>
    </collision>
    <inertial>
      <mass value="2.0"/>
      <inertia ixx="1e-3" ixy="1e-3" ixz="1e-3" iyy="1e-3" iyz="1e-3" izz="1e-3"/>
    </inertial>
  </link>
  <joint name="left_bar_joint" type="fixed">
    <axis xyz="0 0 0"/>
    <parent link="base_link"/>
    <child link="left_bar"/>
    <origin rpy="0 0 0" xyz="0.0 -0.3215 -0.446625"/>
    <!--chair_height/4 + chair_height/8 because this is relative to the center of the bar -->
  </joint>
  <!--Main Wheels -->
  <joint name="right_main_wheel_joint" type="continuous">
    <axis xyz="0 0 -1"/>
    <parent link="right_bar"/>
    <child link="right_main_wheel"/>
    <origin rpy="1.57075 0 0" xyz="0.0 0.0 -0.072875"/>
  </joint>
  <link name="right_main_wheel">
    <visual>
      <geometry>
        <cylinder length="0.065" radius="0.165"/>
      </geometry>
      <material name="white">
        <color rgba="0 0 0 1"/>
      </material>
    </visual>
    <collision>
      <geometry>
        <cylinder length="0.065" radius="0.165"/>
      </geometry>
    </collision>
    <inertial>
      <mass value="2.0"/>
      <inertia ixx="0.0143166666667" ixy="0" ixz="0" iyy="0.0143166666667" iyz="0" izz="0.027225"/>
    </inertial>
  </link>
  <joint name="left_main_wheel_joint" type="continuous">
    <axis xyz="0 0 -1"/>
    <parent link="left_bar"/>
    <child link="left_main_wheel"/>
    <origin rpy="1.57075 0 0" xyz="0.0 0.0 -0.072875"/>
  </joint>
  <link name="left_main_wheel">
    <visual>
      <geometry>
        <cylinder length="0.065" radius="0.165"/>
      </geometry>
      <material name="white">
        <color rgba="0 0 0 1"/>
      </material>
    </visual>
    <collision>
      <geometry>
        <cylinder length="0.065" radius="0.165"/>
      </geometry>
    </collision>
    <inertial>
      <mass value="2.0"/>
      <inertia ixx="0.0143166666667" ixy="0" ixz="0" iyy="0.0143166666667" iyz="0" izz="0.027225"/>
    </inertial>
  </link>
  <!--Laser Scanners -->
  <link name="right_scanner">
    <visual>
      <origin rpy="0 0 0" xyz="0.0 0 0"/>
      <geometry>
        <box size="0.05 0.05 0.1"/>
      </geometry>
    </visual>
    <collision>
      <geometry>
        <box size="0.05 0.05 0.1"/>
      </geometry>
    </collision>
    <inertial>
      <mass value="1e-5"/>
      <inertia ixx="1e-3" ixy="0" ixz="0" iyy="1e-3" iyz="0" izz="1e-3"/>
    </inertial>
  </link>
  <joint name="right_scanner_joint" type="fixed">
    <axis xyz="0 0 0"/>
    <origin rpy="0 0 0" xyz="0.4825 -0.025 0.1244375"/>
    <parent link="right_bar"/>
    <child link="right_scanner"/>
  </joint>
  <link name="left_scanner">
    <visual>
      <origin rpy="0 0 0" xyz="0.0 0 0"/>
      <geometry>
        <box size="0.05 0.05 0.1"/>
      </geometry>
    </visual>
    <collision>
      <geometry>
        <box size="0.05 0.05 0.1"/>
      </geometry>
    </collision>
    <inertial>
      <mass value="1e-5"/>
      <inertia ixx="1e-3" ixy="0" ixz="0" iyy="1e-3" iyz="0" izz="1e-3"/>
    </inertial>
  </link>
  <joint name="left_scanner_joint" type="fixed">
    <axis xyz="0 0 0"/>
    <origin rpy="0 0 -3.14159265359" xyz="0.4825 -0.025 0.1244375"/>
    <parent link="left_bar"/>
    <child link="left_scanner"/>
  </joint>
  <!--Front Wheels -->
  <link name="front_right_swivel">
    <visual>
      <geometry>
        <cylinder length="0.065" radius="0.01"/>
      </geometry>
      <material name="white">
        <color rgba="0 0 0 1"/>
      </material>
    </visual>
    <collision>
      <geometry>
        <cylinder length="0.065" radius="0.01"/>
      </geometry>
    </collision>
    <inertial>
      <mass value="1.0"/>
      <inertia ixx="1e-3" ixy="1e-3" ixz="1e-3" iyy="1e-3" iyz="1e-3" izz="1e-3"/>
    </inertial>
  </link>
  <joint name="front_right_swivel_joint" type="continuous">
    <axis xyz="0 0 1"/>
    <parent link="right_bar"/>
    <child link="front_right_swivel"/>
    <origin rpy="0 0 0" xyz="-0.406 0.0 -0.148875"/>
    <dynamics damping="0.0" friction="0.5"/>
  </joint>
  <joint name="front_right_wheel_joint" type="continuous">
    <axis xyz="0 0 1"/>
    <parent link="front_right_swivel"/>
    <child link="front_right_wheel"/>
    <origin rpy="1.57075 0 0" xyz="0.065 0 0"/>
    <dynamics damping="1.0" friction="1.5"/>
  </joint>
  <link name="front_right_wheel">
    <visual>
      <geometry>
        <cylinder length="0.05" radius="0.089"/>
      </geometry>
      <material name="white">
        <color rgba="0 0 0 1"/>
      </material>
    </visual>
    <collision>
      <geometry>
        <cylinder length="0.05" radius="0.089"/>
      </geometry>
      <surface>
        <friction>
          <ode>
            <mu>1.0</mu>
            <mu2>1.0</mu2>
          </ode>
        </friction>
      </surface>
    </collision>
    <inertial>
      <mass value="1.0"/>
      <inertia ixx="0.00218858333333" ixy="0" ixz="0" iyy="0.00218858333333" iyz="0" izz="0.0039605"/>
    </inertial>
  </link>
  <link name="front_left_swivel">
    <visual>
      <geometry>
        <cylinder length="0.065" radius="0.01"/>
      </geometry>
      <material name="white">
        <color rgba="0 0 0 1"/>
      </material>
    </visual>
    <collision>
      <geometry>
        <cylinder length="0.065" radius="0.01"/>
      </geometry>
    </collision>
    <inertial>
      <mass value="1.0"/>
      <inertia ixx="1e-3" ixy="1e-3" ixz="1e-3" iyy="1e-3" iyz="1e-3" izz="1e-3"/>
    </inertial>
  </link>
  <joint name="front_left_swivel_joint" type="continuous">
    <axis xyz="0 0 1"/>
    <parent link="left_bar"/>
    <child link="front_left_swivel"/>
    <origin rpy="0 0 0" xyz="-0.406 0.0 -0.148875"/>
    <dynamics damping="0.0" friction="0.5"/>
  </joint>
  <joint name="front_left_wheel_joint" type="continuous">
    <axis xyz="0 0 1"/>
    <parent link="front_left_swivel"/>
    <child link="front_left_wheel"/>
    <origin rpy="1.57075 0 0" xyz="0.065 0 0"/>
    <dynamics damping="0" friction="0.5"/>
  </joint>
  <link name="front_left_wheel">
    <visual>
      <geometry>
        <cylinder length="0.05" radius="0.089"/>
      </geometry>
      <material name="white">
        <color rgba="0 0 0 1"/>
      </material>
    </visual>
    <collision>
      <geometry>
        <cylinder length="0.05" radius="0.089"/>
      </geometry>
      <surface>
        <friction>
          <ode>
            <mu>1.0</mu>
            <mu2>1.0</mu2>
          </ode>
        </friction>
      </surface>
    </collision>
    <inertial>
      <mass value="1.0"/>
      <inertia ixx="0.00218858333333" ixy="0" ixz="0" iyy="0.00218858333333" iyz="0" izz="0.0039605"/>
    </inertial>
  </link>
  <!--Rear Wheels -->
  <link name="rear_right_swivel">
    <visual>
      <geometry>
        <cylinder length="0.065" radius="0.01"/>
      </geometry>
      <material name="white">
        <color rgba="0 0 0 1"/>
      </material>
    </visual>
    <collision>
      <geometry>
        <cylinder length="0.065" radius="0.01"/>
      </geometry>
    </collision>
    <inertial>
      <mass value="1.0"/>
      <inertia ixx="1e-3" ixy="1e-3" ixz="1e-3" iyy="1e-3" iyz="1e-3" izz="1e-3"/>
    </inertial>
  </link>
  <joint name="rear_right_swivel_joint" type="continuous">
    <axis xyz="0 0 1"/>
    <parent link="right_bar"/>
    <child link="rear_right_swivel"/>
    <origin rpy="0 0 0" xyz="0.406 0.0 -0.148875"/>
    <dynamics damping="0.0" friction="0.5"/>
  </joint>
  <joint name="rear_right_wheel_joint" type="continuous">
    <axis xyz="0 0 1"/>
    <parent link="rear_right_swivel"/>
    <child link="rear_right_wheel"/>
    <origin rpy="1.57075 0 0" xyz="0.065 0 0"/>
    <dynamics damping="0" friction="0.5"/>
  </joint>
  <link name="rear_right_wheel">
    <visual>
      <geometry>
        <cylinder length="0.05" radius="0.089"/>
      </geometry>
      <material name="white">
        <color rgba="0 0 0 1"/>
      </material>
    </visual>
    <collision>
      <geometry>
        <cylinder length="0.05" radius="0.089"/>
      </geometry>
      <surface>
        <friction>
          <ode>
            <mu>1.0</mu>
            <mu2>1.0</mu2>
          </ode>
        </friction>
      </surface>
    </collision>
    <inertial>
      <mass value="1.0"/>
      <inertia ixx="0.00218858333333" ixy="0" ixz="0" iyy="0.00218858333333" iyz="0" izz="0.0039605"/>
    </inertial>
  </link>
  <link name="rear_left_swivel">
    <visual>
      <geometry>
        <cylinder length="0.065" radius="0.01"/>
      </geometry>
      <material name="white">
        <color rgba="0 0 0 1"/>
      </material>
    </visual>
    <collision>
      <geometry>
        <cylinder length="0.065" radius="0.01"/>
      </geometry>
    </collision>
    <inertial>
      <mass value="1.0"/>
      <inertia ixx="1e-3" ixy="1e-3" ixz="1e-3" iyy="1e-3" iyz="1e-3" izz="1e-3"/>
    </inertial>
  </link>
  <joint name="rear_left_swivel_joint" type="continuous">
    <axis xyz="0 0 1"/>
    <parent link="left_bar"/>
    <child link="rear_left_swivel"/>
    <origin rpy="0 0 0" xyz="0.406 0.0 -0.148875"/>
    <dynamics damping="0.0" friction="0.5"/>
  </joint>
  <joint name="rear_left_wheel_joint" type="continuous">
    <axis xyz="0 0 1"/>
    <parent link="rear_left_swivel"/>
    <child link="rear_left_wheel"/>
    <origin rpy="1.57075 0 0" xyz="0.065 0 0"/>
    <dynamics damping="0" friction="0.5"/>
  </joint>
  <link name="rear_left_wheel">
    <visual>
      <geometry>
        <cylinder length="0.05" radius="0.089"/>
      </geometry>
      <material name="white">
        <color rgba="0 0 0 1"/>
      </material>
    </visual>
    <collision>
      <geometry>
        <cylinder length="0.05" radius="0.089"/>
      </geometry>
      <surface>
        <friction>
          <ode>
            <mu>1.0</mu>
            <mu2>1.0</mu2>
          </ode>
        </friction>
      </surface>
    </collision>
    <inertial>
      <mass value="1.0"/>
      <inertia ixx="0.00218858333333" ixy="0" ixz="0" iyy="0.00218858333333" iyz="0" izz="0.0039605"/>
    </inertial>
  </link>
  <!-- <gazebo> -->
  <!--   <plugin filename="libgazebo_ros_diff_drive.so" name="differential_drive_controller"> -->
  <!--     <alwaysOn>true</alwaysOn> -->
  <!--     <updateRate>50</updateRate> -->
  <!--     <leftJoint>left_main_wheel_joint</leftJoint> -->
  <!--     <rightJoint>right_main_wheel_joint</rightJoint> -->
  <!--     <wheelSeparation>0.643</wheelSeparation> -->
  <!--     <wheelDiameter>0.33</wheelDiameter> -->
  <!--     <torque>20</torque> -->
  <!--     <commandTopic>cmd_vel</commandTopic> -->
  <!--     <odometryTopic>odom</odometryTopic> -->
  <!--     <odometryFrame>odom</odometryFrame> -->
  <!--     <robotBaseFrame>base_footprint</robotBaseFrame> -->
  <!--   </plugin> -->
  <!-- </gazebo> -->
  <gazebo reference="right_scanner">
    <sensor name="head_hokuyo_sensor" type="gpu_ray">
      <pose>0 0 0 0 0 0</pose>
      <visualize>false</visualize>
      <update_rate>40</update_rate>
      <ray>
        <scan>
          <horizontal>
            <samples>720</samples>
            <resolution>1</resolution>
            <min_angle>0</min_angle>
            <max_angle>3.14159265359</max_angle>
          </horizontal>
        </scan>
        <range>
          <min>0.10</min>
          <max>30.0</max>
          <resolution>0.01</resolution>
        </range>
        <noise>
          <type>gaussian</type>
          <mean>0.0</mean>
          <stddev>0.01</stddev>
        </noise>
      </ray>
      <plugin filename="libgazebo_ros_gpu_laser.so" name="gazebo_ros_head_hokuyo_controller">
        <topicName>/wheelchair_lasers/right</topicName>
        <frameName>right_scanner</frameName>
      </plugin>
    </sensor>
  </gazebo>
  <gazebo reference="left_scanner">
    <sensor name="head_hokuyo_sensor2" type="gpu_ray">
      <pose>0 0 0 0 0 0</pose>
      <visualize>true</visualize>
      <update_rate>40</update_rate>
      <ray>
        <scan>
          <horizontal>
            <samples>720</samples>
            <resolution>1</resolution>
            <min_angle>0</min_angle>
            <max_angle>3.14159265359</max_angle>
          </horizontal>
        </scan>
        <range>
          <min>0.10</min>
          <max>30.0</max>
          <resolution>0.01</resolution>
        </range>
        <noise>
          <type>gaussian</type>
          <mean>0.0</mean>
          <stddev>0.01</stddev>
        </noise>
      </ray>
      <plugin filename="libgazebo_ros_gpu_laser.so" name="gazebo_ros_head_hokuyo_controller2">
        <topicName>/wheelchair_lasers/left</topicName>
        <frameName>left_scanner</frameName>
      </plugin>
    </sensor>
  </gazebo>
</robot>


